<?xml version="1.0" encoding="utf-8"?>

<robot xmlns:xacro="http://www.ros.org/wiki/xacro" name="New_bot">
  
  <link
    name="base_link">
    <inertial>
      <origin
        xyz="0.040091 -0.070548 0.0053142"
        rpy="0 0 0" />
      <mass
        value="1.0963" />
      <inertia
        ixx="0.002087"
        ixy="-5.3193E-13"
        ixz="-9.8151E-08"
        iyy="0.0040225"
        iyz="-6.4781E-06"
        izz="0.0021816" />
    </inertial>
    <visual>
      <origin
        xyz="0 0 0"
        rpy="0 0 0" />
      <geometry>
        <mesh
          filename="package://mrs_gazebo_sim/meshes/base_link.STL" />
      </geometry>
      <material
        name="">
        <color
          rgba="0 0 1 1" />
      </material>
    </visual>
    <collision>
      <origin
        xyz="0 0 0"
        rpy="0 0 0" />
      <geometry>
        <mesh
          filename="package://mrs_gazebo_sim/meshes/base_link.STL" />
      </geometry>
    </collision>
  </link>
  <link
    name="Wheel1_link">
    <inertial>
      <origin
        xyz="5.4288E-13 2.1436E-13 -0.021"
        rpy="0 0 0" />
      <mass
        value="1.032594" />
      <inertia
        ixx="5.9455E-06"
        ixy="-2.7256E-11"
        ixz="4.5429E-19"
        iyy="5.9455E-06"
        iyz="6.0965E-20"
        izz="9.7181E-06" />
    </inertial>
    <visual>
      <origin
        xyz="0 0 0"
        rpy="0 0 0" />
      <geometry>
        <mesh
          filename="package://mrs_gazebo_sim/meshes/Wheel1_link.STL" />
      </geometry>
      <material
        name="">
        <color
          rgba="1 0 0 1" />
      </material>
    </visual>
    <collision>
      <origin
        xyz="0 0 0"
        rpy="0 0 0" />
      <geometry>
        <mesh
          filename="package://mrs_gazebo_sim/meshes/Wheel1_link.STL" />
      </geometry>
    </collision>
  </link>
  <joint
    name="Whee1_joint"
    type="continuous">
    <origin
      xyz="-0.065909 -0.055678 -0.090096"
      rpy="-1.5708 0 1.5708" />
    <parent
      link="base_link" />
    <child
      link="Wheel1_link" />
    <axis
      xyz="0 0 1" />
  </joint>
  <link
    name="Whee2_link">
    <inertial>
      <origin
        xyz="-3.0542E-09 1.8674E-08 -0.021"
        rpy="0 0 0" />
      <mass
        value="1.032594" />
      <inertia
        ixx="5.9455E-06"
        ixy="3.2885E-11"
        ixz="-3.774E-13"
        iyy="5.9455E-06"
        iyz="1.1594E-12"
        izz="9.7181E-06" />
    </inertial>
    <visual>
      <origin
        xyz="0 0 0"
        rpy="0 0 0" />
      <geometry>
        <mesh
          filename="package://mrs_gazebo_sim/meshes/Whee2_link.STL" />
      </geometry>
      <material
        name="">
        <color
          rgba="1 0 0 1" />
      </material>
    </visual>
    <collision>
      <origin
        xyz="0 0 0"
        rpy="0 0 0" />
      <geometry>
        <mesh
          filename="package://mrs_gazebo_sim/meshes/Whee2_link.STL" />
      </geometry>
    </collision>
  </link>
  <joint
    name="Wheel2_joint"
    type="continuous">
    <origin
      xyz="0.14609 -0.053678 -0.090096"
      rpy="1.5708 0 1.5708" />
    <parent
      link="base_link" />
    <child
      link="Whee2_link" />
    <axis
      xyz="0 0 1" />
  </joint>
  <link
    name="Grip1_link">
    <inertial>
      <origin
        xyz="0.097891 0.0052987 0.00375"
        rpy="0 0 0" />
      <mass
        value="0.003614" />
      <inertia
        ixx="8.7988E-06"
        ixy="-2.2778E-06"
        ixz="7.3191E-13"
        iyy="4.174E-05"
        iyz="8.7797E-14"
        izz="5.02E-05" />
    </inertial>
    <visual>
      <origin
        xyz="0 0 0"
        rpy="0 0 0" />
      <geometry>
        <mesh
          filename="package://mrs_gazebo_sim/meshes/Grip1_link.STL" />
      </geometry>
      <material
        name="">
        <color
          rgba="0 1 0 1" />
      </material>
    </visual>
    <collision>
      <origin
        xyz="0 0 0"
        rpy="0 0 0" />
      <geometry>
        <mesh
          filename="package://mrs_gazebo_sim/meshes/Grip1_link.STL" />
      </geometry>
    </collision>
  </link>
  <joint
    name="Grip1_joint"
    type="prismatic">
    <origin
      xyz="0.079011 0.061322 -0.065096"
      rpy="1.5708 0 1.5708" />
    <parent
      link="base_link" />
    <child
      link="Grip1_link" />
    <axis
      xyz="0 0 1" />
    <limit
      lower="-0.002"
      upper="0.0025"
      effort="1"
      velocity="0.2" />
  </joint>
  <link
    name="Grip2_link">
    <inertial>
      <origin
        xyz="0.097891 -0.0052987 0.00375"
        rpy="0 0 0" />
      <mass
        value="0.003614" />
      <inertia
        ixx="8.7988E-06"
        ixy="2.2778E-06"
        ixz="-7.3191E-13"
        iyy="4.174E-05"
        iyz="8.7789E-14"
        izz="5.02E-05" />
    </inertial>
    <visual>
      <origin
        xyz="0 0 0"
        rpy="0 0 0" />
      <geometry>
        <mesh
          filename="package://mrs_gazebo_sim/meshes/Grip2_link.STL" />
      </geometry>
      <material
        name="">
        <color
          rgba="0 1 0 1" />
      </material>
    </visual>
    <collision>
      <origin
        xyz="0 0 0"
        rpy="0 0 0" />
      <geometry>
        <mesh
          filename="package://mrs_gazebo_sim/meshes/Grip2_link.STL" />
      </geometry>
    </collision>
  </link>
  <joint
    name="Grip2_joint"
    type="prismatic">
    <origin
      xyz="0.014667 0.061322 -0.065096"
      rpy="-1.5708 0 1.5708" />
    <parent
      link="base_link" />
    <child
      link="Grip2_link" />
    <axis
      xyz="0 0 1" />
    <limit
      lower="-0.01"
      upper="0.015"
      effort="1"
      velocity="0.2" />
  </joint>
</robot>
