<?xml version="1.0" encoding="utf-8"?>
<!-- This URDF was automatically created by SolidWorks to URDF Exporter! Originally created by Stephen Brawner (brawner@gmail.com) 
     Commit Version: 1.6.0-4-g7f85cfe  Build Version: 1.6.7995.38578
     For more information, please see http://wiki.ros.org/sw_urdf_exporter -->
<robot
  name="URDF_bot_final_2">
  <link
    name="base_link">
    <inertial>
      <origin
        xyz="8.60422844084496E-16 -0.00697001255399204 -0.113640401660277"
        rpy="0 0 0" />
      <mass
        value="26.8879845162854" />
      <inertia
        ixx="0.385139507707689"
        ixy="-3.51992200976601E-16"
        ixz="-9.6673037334202E-16"
        iyy="0.376289539605871"
        iyz="0.000682246181241517"
        izz="0.521493886642275" />
    </inertial>
    <visual>
      <origin
        xyz="0 0 0"
        rpy="0 0 0" />
      <geometry>
        <mesh
          filename="package://URDF_bot_final_2/meshes/base_link.STL" />
      </geometry>
      <material
        name="">
        <color
          rgba="0.792156862745098 0.819607843137255 0.933333333333333 1" />
      </material>
    </visual>
    <collision>
      <origin
        xyz="0 0 0"
        rpy="0 0 0" />
      <geometry>
        <mesh
          filename="package://URDF_bot_final_2/meshes/base_link.STL" />
      </geometry>
    </collision>
  </link>
  <link
    name="W_L">
    <inertial>
      <origin
        xyz="-1.11022302462516E-15 0.0202816466241088 5.55111512312578E-17"
        rpy="0 0 0" />
      <mass
        value="0.56046012382194" />
      <inertia
        ixx="0.000964865107374987"
        ixy="2.80987895356466E-18"
        ixz="-1.1664625765267E-19"
        iyy="0.00178033491000625"
        iyz="5.96074138738194E-19"
        izz="0.000964925835650445" />
    </inertial>
    <visual>
      <origin
        xyz="0 0 0"
        rpy="0 0 0" />
      <geometry>
        <mesh
          filename="package://URDF_bot_final_2/meshes/W_L.STL" />
      </geometry>
      <material
        name="">
        <color
          rgba="0.792156862745098 0.819607843137255 0.933333333333333 1" />
      </material>
    </visual>
    <collision>
      <origin
        xyz="0 0 0"
        rpy="0 0 0" />
      <geometry>
        <mesh
          filename="package://URDF_bot_final_2/meshes/W_L.STL" />
      </geometry>
    </collision>
  </link>
  <joint
    name="W_L_link"
    type="continuous">
    <origin
      xyz="-0.239999999999999 0 -0.205000000000002"
      rpy="-3.14159265358979 0 1.5707963267949" />
    <parent
      link="base_link" />
    <child
      link="W_L" />
    <axis
      xyz="0 1 0" />
  </joint>
  <link
    name="W_R">
    <inertial>
      <origin
        xyz="-5.55111512312578E-17 -0.0202816466241043 -4.16333634234434E-16"
        rpy="0 0 0" />
      <mass
        value="0.56046012382194" />
      <inertia
        ixx="0.000964865107374987"
        ixy="-3.09970833166368E-18"
        ixz="7.88018780428268E-20"
        iyy="0.00178033491000625"
        iyz="-1.25295594502704E-17"
        izz="0.000964925835650445" />
    </inertial>
    <visual>
      <origin
        xyz="0 0 0"
        rpy="0 0 0" />
      <geometry>
        <mesh
          filename="package://URDF_bot_final_2/meshes/W_R.STL" />
      </geometry>
      <material
        name="">
        <color
          rgba="0.792156862745098 0.819607843137255 0.933333333333333 1" />
      </material>
    </visual>
    <collision>
      <origin
        xyz="0 0 0"
        rpy="0 0 0" />
      <geometry>
        <mesh
          filename="package://URDF_bot_final_2/meshes/W_R.STL" />
      </geometry>
    </collision>
  </link>
  <joint
    name="W_R_link"
    type="continuous">
    <origin
      xyz="0.240000000000001 0 -0.204999999999999"
      rpy="-3.14159265358979 0 1.5707963267949" />
    <parent
      link="base_link" />
    <child
      link="W_R" />
    <axis
      xyz="0 -1 0" />
  </joint>
  <link
    name="P1_R">
    <inertial>
      <origin
        xyz="0.0074999999999997 0 0"
        rpy="0 0 0" />
      <mass
        value="0.0461780972450962" />
      <inertia
        ixx="5.12918276753618E-05"
        ixy="-1.24143784260085E-19"
        ixz="1.05369012081565E-20"
        iyy="4.60163160465626E-06"
        iyz="-4.44692297308508E-20"
        izz="4.84218747173967E-05" />
    </inertial>
    <visual>
      <origin
        xyz="0 0 0"
        rpy="0 0 0" />
      <geometry>
        <mesh
          filename="package://URDF_bot_final_2/meshes/P1_R.STL" />
      </geometry>
      <material
        name="">
        <color
          rgba="0.792156862745098 0.819607843137255 0.933333333333333 1" />
      </material>
    </visual>
    <collision>
      <origin
        xyz="0 0 0"
        rpy="0 0 0" />
      <geometry>
        <mesh
          filename="package://URDF_bot_final_2/meshes/P1_R.STL" />
      </geometry>
    </collision>
  </link>
  <joint
    name="P1_R_Link"
    type="prismatic">
    <origin
      xyz="0.154649736298411 0.148648533555594 -0.182094440280863"
      rpy="0.870370202775625 1.5707963267949 0" />
    <parent
      link="base_link" />
    <child
      link="P1_R" />
    <axis
      xyz="-1 0 0" />
    <limit
      lower="0"
      upper="0.15"
      effort="0"
      velocity="0" />
  </joint>
  <link
    name="R1_R">
    <inertial>
      <origin
        xyz="0.00750000000000009 0.05 5.55111512312578E-17"
        rpy="0 0 0" />
      <mass
        value="0.0461780972450962" />
      <inertia
        ixx="5.12918276753618E-05"
        ixy="1.7461282703913E-19"
        ixz="2.56580136426819E-21"
        iyy="4.60163160465626E-06"
        iyz="-1.0068607852118E-19"
        izz="4.84218747173967E-05" />
    </inertial>
    <visual>
      <origin
        xyz="0 0 0"
        rpy="0 0 0" />
      <geometry>
        <mesh
          filename="package://URDF_bot_final_2/meshes/R1_R.STL" />
      </geometry>
      <material
        name="">
        <color
          rgba="0.792156862745098 0.819607843137255 0.933333333333333 1" />
      </material>
    </visual>
    <collision>
      <origin
        xyz="0 0 0"
        rpy="0 0 0" />
      <geometry>
        <mesh
          filename="package://URDF_bot_final_2/meshes/R1_R.STL" />
      </geometry>
    </collision>
  </link>
  <joint
    name="R1_R_J"
    type="revolute">
    <origin
      xyz="0 0.0500000000000001 0"
      rpy="-2.26886705484522 0 3.14159265358979" />
    <parent
      link="P1_R" />
    <child
      link="R1_R" />
    <axis
      xyz="1 0 0" />
    <limit
      lower="-1.57"
      upper="0.78"
      effort="0"
      velocity="0" />
  </joint>
  <link
    name="R2_R">
    <inertial>
      <origin
        xyz="0.0231462742976176 -0.0659326410357274 0.000249370283456174"
        rpy="0 0 0" />
      <mass
        value="0.0668390486225481" />
      <inertia
        ixx="0.000100971656034691"
        ixy="1.60498639595143E-06"
        ixz="-2.3109653704175E-08"
        iyy="2.07628535797184E-05"
        iyz="6.19297276668896E-07"
        izz="9.08923415643615E-05" />
    </inertial>
    <visual>
      <origin
        xyz="0 0 0"
        rpy="0 0 0" />
      <geometry>
        <mesh
          filename="package://URDF_bot_final_2/meshes/R2_R.STL" />
      </geometry>
      <material
        name="">
        <color
          rgba="0.792156862745098 0.819607843137255 0.933333333333333 1" />
      </material>
    </visual>
    <collision>
      <origin
        xyz="0 0 0"
        rpy="0 0 0" />
      <geometry>
        <mesh
          filename="package://URDF_bot_final_2/meshes/R2_R.STL" />
      </geometry>
    </collision>
  </link>
  <joint
    name="R2_R_J"
    type="revolute">
    <origin
      xyz="0 0.1 0"
      rpy="-3.13374920384741 0 0" />
    <parent
      link="R1_R" />
    <child
      link="R2_R" />
    <axis
      xyz="1 0 0" />
    <limit
      lower="-0.52"
      upper="0.52"
      effort="0"
      velocity="0" />
  </joint>
  <link
    name="P2_L">
    <inertial>
      <origin
        xyz="0.00749999999999984 5.55111512312578E-17 2.77555756156289E-17"
        rpy="0 0 0" />
      <mass
        value="0.0461780972450962" />
      <inertia
        ixx="5.12918276753618E-05"
        ixy="9.29088277330331E-20"
        ixz="8.06265920000474E-21"
        iyy="4.60163160465626E-06"
        iyz="1.56701095242046E-20"
        izz="4.84218747173967E-05" />
    </inertial>
    <visual>
      <origin
        xyz="0 0 0"
        rpy="0 0 0" />
      <geometry>
        <mesh
          filename="package://URDF_bot_final_2/meshes/P2_L.STL" />
      </geometry>
      <material
        name="">
        <color
          rgba="0.792156862745098 0.819607843137255 0.933333333333333 1" />
      </material>
    </visual>
    <collision>
      <origin
        xyz="0 0 0"
        rpy="0 0 0" />
      <geometry>
        <mesh
          filename="package://URDF_bot_final_2/meshes/P2_L.STL" />
      </geometry>
    </collision>
  </link>
  <joint
    name="P2_L_link"
    type="prismatic">
    <origin
      xyz="-0.153814757931836 0.149613727495049 -0.181781659152969"
      rpy="2.29674794123281 1.5707963267949 0" />
    <parent
      link="base_link" />
    <child
      link="P2_L" />
    <axis
      xyz="-1 0 0" />
    <limit
      lower="0"
      upper="0.15"
      effort="0"
      velocity="0" />
  </joint>
  <link
    name="R1_L">
    <inertial>
      <origin
        xyz="0.00749999999999995 0.05 3.46944695195361E-18"
        rpy="0 0 0" />
      <mass
        value="0.0461780972450962" />
      <inertia
        ixx="5.12918276753618E-05"
        ixy="1.78121309247091E-19"
        ixz="-1.80996776417054E-22"
        iyy="4.60163160465626E-06"
        iyz="1.6675961149069E-21"
        izz="4.84218747173967E-05" />
    </inertial>
    <visual>
      <origin
        xyz="0 0 0"
        rpy="0 0 0" />
      <geometry>
        <mesh
          filename="package://URDF_bot_final_2/meshes/R1_L.STL" />
      </geometry>
      <material
        name="">
        <color
          rgba="0.792156862745098 0.819607843137255 0.933333333333333 1" />
      </material>
    </visual>
    <collision>
      <origin
        xyz="0 0 0"
        rpy="0 0 0" />
      <geometry>
        <mesh
          filename="package://URDF_bot_final_2/meshes/R1_L.STL" />
      </geometry>
    </collision>
  </link>
  <joint
    name="R1_L_J"
    type="revolute">
    <origin
      xyz="0 -0.0499999999999992 0"
      rpy="-0.801705358052037 0 3.14159265358979" />
    <parent
      link="P2_L" />
    <child
      link="R1_L" />
    <axis
      xyz="1 0 0" />
    <limit
      lower="-0.78"
      upper="1.57"
      effort="0"
      velocity="0" />
  </joint>
  <link
    name="R2_L">
    <inertial>
      <origin
        xyz="-0.0218537257023807 -0.0659326410357276 0.000249370283452909"
        rpy="0 0 0" />
      <mass
        value="0.0668390486225481" />
      <inertia
        ixx="0.000100971656034691"
        ixy="1.60498639595202E-06"
        ixz="-2.31096537041645E-08"
        iyy="2.07628535797184E-05"
        iyz="6.19297276668749E-07"
        izz="9.08923415643614E-05" />
    </inertial>
    <visual>
      <origin
        xyz="0 0 0"
        rpy="0 0 0" />
      <geometry>
        <mesh
          filename="package://URDF_bot_final_2/meshes/R2_L.STL" />
      </geometry>
      <material
        name="">
        <color
          rgba="0.792156862745098 0.819607843137255 0.933333333333333 1" />
      </material>
    </visual>
    <collision>
      <origin
        xyz="0 0 0"
        rpy="0 0 0" />
      <geometry>
        <mesh
          filename="package://URDF_bot_final_2/meshes/R2_L.STL" />
      </geometry>
    </collision>
  </link>
  <joint
    name="R2_L_link"
    type="revolute">
    <origin
      xyz="0 0.1 0"
      rpy="0.00784344973856893 0 -3.14159265358979" />
    <parent
      link="R1_L" />
    <child
      link="R2_L" />
    <axis
      xyz="1 0 0" />
    <limit
      lower="-0.52"
      upper="0.52"
      effort="0"
      velocity="0" />
  </joint>
</robot>